Workbook

Sheet Mom's Portfolio
A1: Phantom wallet 5 (starting with $9000)
A2: USDC vault
A3: Jito/SOL
A4: SOL vault
A6: All of them on Kamino for now.

Sheet Baskets
A1: Drone Basket
A2: Company | B2: Price | C2: Number of shares | D2: Value | E2: Employees | F2: MarketCap | G2: P/E | H2: Beta | I2: Marketcap per employee | J2: Share of portfolio
A3: #VALUE! | B3: {=_FV(A3,"Price")} -> 16.05 | C3: 88.731145 | D3: =IFERROR(Table1[[#This Row],[Price]]*Table1[[#This Row],[Number of shares]],0) -> 1424.1349 | E3: {=_FV(Table1[[#This Row],[Company]],"Employees")} -> 115 | F3: {=_FV(Table1[[#This Row],[Company]],"Market cap",TRUE)} -> 1944277740 | G3: {=_FV(Table1[[#This Row],[Company]],"P/E",TRUE)} -> 0 | H3: {=_FV(Table1[[#This Row],[Company]],"Beta")} -> 1.2419 | I3: =Table1[[#This Row],[MarketCap]]/Table1[[#This Row],[Employees]] -> 16906763 | J3: =Table1[[#This Row],[Value]] / SUM(Table1[Value]) -> 0.091773127
A4: #VALUE! | B4: {=_FV(A4,"Price")} -> 71.38 | C4: 24.931439 | D4: =IFERROR(Table1[[#This Row],[Price]]*Table1[[#This Row],[Number of shares]],0) -> 1779.6061 | E4: {=_FV(Table1[[#This Row],[Company]],"Employees")} -> 226 | F4: {=_FV(Table1[[#This Row],[Company]],"Market cap",TRUE)} -> 250688701 | G4: {=_FV(Table1[[#This Row],[Company]],"P/E",TRUE)} -> 29.8025 | H4: {=_FV(Table1[[#This Row],[Company]],"Beta")} -> 0.6598 | I4: =Table1[[#This Row],[MarketCap]]/Table1[[#This Row],[Employees]] -> 1109242 | J4: =Table1[[#This Row],[Value]] / SUM(Table1[Value]) -> 0.11468016
A5: #VALUE! | B5: {=_FV(A5,"Price")} -> 14.73 | C5: 91.99632 | D5: =IFERROR(Table1[[#This Row],[Price]]*Table1[[#This Row],[Number of shares]],0) -> 1355.1058 | E5: {=_FV(Table1[[#This Row],[Company]],"Employees")} -> 141 | F5: {=_FV(Table1[[#This Row],[Company]],"Market cap",TRUE)} -> 703866421 | G5: {=_FV(Table1[[#This Row],[Company]],"P/E",TRUE)} -> #VALUE! | H5: {=_FV(Table1[[#This Row],[Company]],"Beta")} -> 3.338 | I5: =Table1[[#This Row],[MarketCap]]/Table1[[#This Row],[Employees]] -> 4991960.4 | J5: =Table1[[#This Row],[Value]] / SUM(Table1[Value]) -> 0.087324802
A6: #VALUE! | B6: {=_FV(A6,"Price")} -> 201.62 | C6: 3.6492355 | D6: =IFERROR(Table1[[#This Row],[Price]]*Table1[[#This Row],[Number of shares]],0) -> 735.75886 | E6: {=_FV(Table1[[#This Row],[Company]],"Employees")} -> 1456 | F6: {=_FV(Table1[[#This Row],[Company]],"Market cap",TRUE)} -> 10202994213 | G6: {=_FV(Table1[[#This Row],[Company]],"P/E",TRUE)} -> 0 | H6: {=_FV(Table1[[#This Row],[Company]],"Beta")} -> 1.3456 | I6: =Table1[[#This Row],[MarketCap]]/Table1[[#This Row],[Employees]] -> 7007551 | J6: =Table1[[#This Row],[Value]] / SUM(Table1[Value]) -> 0.04741327
A7: #VALUE! | B7: {=_FV(A7,"Price")} -> 78.195 | C7: 16.91475 | D7: =IFERROR(Table1[[#This Row],[Price]]*Table1[[#This Row],[Number of shares]],0) -> 1322.6488 | E7: {=_FV(Table1[[#This Row],[Company]],"Employees")} -> 4300 | F7: {=_FV(Table1[[#This Row],[Company]],"Market cap",TRUE)} -> 14603518351 | G7: {=_FV(Table1[[#This Row],[Company]],"P/E",TRUE)} -> 594.6388 | H7: {=_FV(Table1[[#This Row],[Company]],"Beta")} -> 1.1771 | I7: =Table1[[#This Row],[MarketCap]]/Table1[[#This Row],[Employees]] -> 3396167.1 | J7: =Table1[[#This Row],[Value]] / SUM(Table1[Value]) -> 0.085233234
A8: #VALUE! | B8: {=_FV(A8,"Price")} -> 10.6 | C8: 448.43049 | D8: =IFERROR(Table1[[#This Row],[Price]]*Table1[[#This Row],[Number of shares]],0) -> 4753.3632 | E8: {=_FV(Table1[[#This Row],[Company]],"Employees")} -> 113 | F8: {=_FV(Table1[[#This Row],[Company]],"Market cap",TRUE)} -> 4943604680 | G8: {=_FV(Table1[[#This Row],[Company]],"P/E",TRUE)} -> 0 | H8: {=_FV(Table1[[#This Row],[Company]],"Beta")} -> 2.5151 | I8: =Table1[[#This Row],[MarketCap]]/Table1[[#This Row],[Employees]] -> 43748714 | J8: =Table1[[#This Row],[Value]] / SUM(Table1[Value]) -> 0.30631299
A9: #VALUE! | B9: {=_FV(A9,"Price")} -> 45.11 | C9: 20.777062 | D9: =IFERROR(Table1[[#This Row],[Price]]*Table1[[#This Row],[Number of shares]],0) -> 937.25327 | E9: {=_FV(Table1[[#This Row],[Company]],"Employees")} -> 7300 | F9: {=_FV(Table1[[#This Row],[Company]],"Market cap",TRUE)} -> 11991248464 | G9: {=_FV(Table1[[#This Row],[Company]],"P/E",TRUE)} -> 43.5845 | H9: {=_FV(Table1[[#This Row],[Company]],"Beta")} -> 0.4389 | I9: =Table1[[#This Row],[MarketCap]]/Table1[[#This Row],[Employees]] -> 1642636.8 | J9: =Table1[[#This Row],[Value]] / SUM(Table1[Value]) -> 0.060397835
A10: #VALUE! | B10: {=_FV(A10,"Price")} -> 628.345 | C10: 1.7741191 | D10: =IFERROR(Table1[[#This Row],[Price]]*Table1[[#This Row],[Number of shares]],0) -> 1114.7589 | E10: {=_FV(Table1[[#This Row],[Company]],"Employees")} -> 15800 | F10: {=_FV(Table1[[#This Row],[Company]],"Market cap",TRUE)} -> 29103231301 | G10: {=_FV(Table1[[#This Row],[Company]],"P/E",TRUE)} -> 33.2852 | H10: {=_FV(Table1[[#This Row],[Company]],"Beta")} -> 0.9929 | I10: =Table1[[#This Row],[MarketCap]]/Table1[[#This Row],[Employees]] -> 1841976.7 | J10: =Table1[[#This Row],[Value]] / SUM(Table1[Value]) -> 0.071836532
A11: #VALUE! | B11: {=_FV(A11,"Price")} -> 907.23 | C11: 2.3096288 | D11: =IFERROR(Table1[[#This Row],[Price]]*Table1[[#This Row],[Number of shares]],0) -> 2095.3646 | E11: {=_FV(Table1[[#This Row],[Company]],"Employees")} -> 19712 | F11: {=_FV(Table1[[#This Row],[Company]],"Market cap",TRUE)} -> 102027000000 | G11: {=_FV(Table1[[#This Row],[Company]],"P/E",TRUE)} -> 90.4374 | H11: {=_FV(Table1[[#This Row],[Company]],"Beta")} -> 0.4644 | I11: =Table1[[#This Row],[MarketCap]]/Table1[[#This Row],[Employees]] -> 5175882.7 | J11: =Table1[[#This Row],[Value]] / SUM(Table1[Value]) -> 0.13502805
A13: (BATS:RCAT*88+BATS:MPTI*25+BATS:UMAC*92+BATS:AVAV*3.64+BATS:KTOS*17+BATS:ONDS*448+BATS:DRS*20.77+BATS:TDY*1.77+BATS:ESLT*2.3)/BATS:SPY
A15: Robotics Basket
A16: Company | B16: Price | C16: Number of shares | D16: Value | E16: Employees | F16: MarketCap | G16: P/E | H16: Beta | I16: Marketcap per employee | J16: Share of Portfolio
A17: #VALUE! | B17: {=_FV(A17,"Price")} -> 212.15 | C17: 5 | D17: =IFERROR(Table13[[#This Row],[Price]]*Table13[[#This Row],[Number of shares]],0) -> 1060.75 | E17: {=_FV(Table13[[#This Row],[Company]],"Employees")} -> 1576000 | F17: {=_FV(Table13[[#This Row],[Company]],"Market cap",TRUE)} -> 2277413278000 | G17: {=_FV(Table13[[#This Row],[Company]],"P/E",TRUE)} -> 29.5795 | H17: {=_FV(Table13[[#This Row],[Company]],"Beta")} -> 1.3909 | I17: =Table13[[#This Row],[MarketCap]]/Table13[[#This Row],[Employees]] -> 1445059.2 | J17: =Table13[[#This Row],[Value]] / SUM(Table13[Value]) -> 0.079259581
A18: #VALUE! | B18: {=_FV(A18,"Price")} -> 323.46 | C18: 11 | D18: =IFERROR(Table13[[#This Row],[Price]]*Table13[[#This Row],[Number of shares]],0) -> 3558.06 | E18: {=_FV(Table13[[#This Row],[Company]],"Employees")} -> 6600 | F18: {=_FV(Table13[[#This Row],[Company]],"Market cap",TRUE)} -> 50639603760 | G18: {=_FV(Table13[[#This Row],[Company]],"P/E",TRUE)} -> 92.8682 | H18: {=_FV(Table13[[#This Row],[Company]],"Beta")} -> 1.7619 | I18: =Table13[[#This Row],[MarketCap]]/Table13[[#This Row],[Employees]] -> 7672667.2 | J18: =Table13[[#This Row],[Value]] / SUM(Table13[Value]) -> 0.26585939
A19: #VALUE! | B19: {=_FV(A19,"Price")} -> 63.68 | C19: 17 | D19: =IFERROR(Table13[[#This Row],[Price]]*Table13[[#This Row],[Number of shares]],0) -> 1082.56 | E19: {=_FV(Table13[[#This Row],[Company]],"Employees")} -> 22600 | F19: {=_FV(Table13[[#This Row],[Company]],"Market cap",TRUE)} -> 25091225440 | G19: {=_FV(Table13[[#This Row],[Company]],"P/E",TRUE)} -> 192.2125 | H19: {=_FV(Table13[[#This Row],[Company]],"Beta")} -> 1.5247 | I19: =Table13[[#This Row],[MarketCap]]/Table13[[#This Row],[Employees]] -> 1110231.2 | J19: =Table13[[#This Row],[Value]] / SUM(Table13[Value]) -> 0.080889232
A20: #VALUE! | B20: {=_FV(A20,"Price")} -> 9.77 | C20: 149 | D20: =IFERROR(Table13[[#This Row],[Price]]*Table13[[#This Row],[Number of shares]],0) -> 1455.73 | E20: {=_FV(Table13[[#This Row],[Company]],"Employees")} -> 190 | F20: {=_FV(Table13[[#This Row],[Company]],"Market cap",TRUE)} -> 2254845656 | G20: {=_FV(Table13[[#This Row],[Company]],"P/E",TRUE)} -> 0 | H20: {=_FV(Table13[[#This Row],[Company]],"Beta")} -> 3.1239 | I20: =Table13[[#This Row],[MarketCap]]/Table13[[#This Row],[Employees]] -> 11867609 | J20: =Table13[[#This Row],[Value]] / SUM(Table13[Value]) -> 0.10877261
A21: #VALUE! | B21: {=_FV(A21,"Price")} -> 3.2 | C21: 220 | D21: =IFERROR(Table13[[#This Row],[Price]]*Table13[[#This Row],[Number of shares]],0) -> 704 | E21: {=_FV(Table13[[#This Row],[Company]],"Employees")} -> 800 | F21: {=_FV(Table13[[#This Row],[Company]],"Market cap",TRUE)} -> 715714240 | G21: {=_FV(Table13[[#This Row],[Company]],"P/E",TRUE)} -> 0 | H21: {=_FV(Table13[[#This Row],[Company]],"Beta")} -> 2.6059 | I21: =Table13[[#This Row],[MarketCap]]/Table13[[#This Row],[Employees]] -> 894642.8 | J21: =Table13[[#This Row],[Value]] / SUM(Table13[Value]) -> 0.052603107
A22: #VALUE! | B22: {=_FV(A22,"Price")} -> 290.39 | C22: 6 | D22: =IFERROR(Table13[[#This Row],[Price]]*Table13[[#This Row],[Number of shares]],0) -> 1742.34 | E22: {=_FV(Table13[[#This Row],[Company]],"Employees")} -> 190820 | F22: {=_FV(Table13[[#This Row],[Company]],"Market cap",TRUE)} -> 3512847830000 | G22: {=_FV(Table13[[#This Row],[Company]],"P/E",TRUE)} -> 26.9032 | H22: {=_FV(Table13[[#This Row],[Company]],"Beta")} -> 1.1251 | I22: =Table13[[#This Row],[MarketCap]]/Table13[[#This Row],[Employees]] -> 18409222 | J22: =Table13[[#This Row],[Value]] / SUM(Table13[Value]) -> 0.13018821
A23: #VALUE! | B23: {=_FV(A23,"Price")} -> 44.77 | C23: 40 | D23: =IFERROR(Table13[[#This Row],[Price]]*Table13[[#This Row],[Number of shares]],0) -> 1790.8 | E23: {=_FV(Table13[[#This Row],[Company]],"Employees")} -> 2100 | F23: {=_FV(Table13[[#This Row],[Company]],"Market cap",TRUE)} -> 595325045 | G23: {=_FV(Table13[[#This Row],[Company]],"P/E",TRUE)} -> 112.8845 | H23: {=_FV(Table13[[#This Row],[Company]],"Beta")} -> 0.9019 | I23: =Table13[[#This Row],[MarketCap]]/Table13[[#This Row],[Employees]] -> 283488.12 | J23: =Table13[[#This Row],[Value]] / SUM(Table13[Value]) -> 0.13380915
A24: #VALUE! | B24: {=_FV(A24,"Price")} -> 36.84 | C24: 35 | D24: =IFERROR(Table13[[#This Row],[Price]]*Table13[[#This Row],[Number of shares]],0) -> 1289.4 | E24: {=_FV(Table13[[#This Row],[Company]],"Employees")} -> 16700 | F24: {=_FV(Table13[[#This Row],[Company]],"Market cap",TRUE)} -> 5371253580 | G24: {=_FV(Table13[[#This Row],[Company]],"P/E",TRUE)} -> 184.847 | H24: {=_FV(Table13[[#This Row],[Company]],"Beta")} -> 1.1191 | I24: =Table13[[#This Row],[MarketCap]]/Table13[[#This Row],[Employees]] -> 321631.95 | J24: =Table13[[#This Row],[Value]] / SUM(Table13[Value]) -> 0.096344383
A25: #VALUE! | B25: {=_FV(A25,"Price")} -> 21.2 | C25: 33 | D25: =IFERROR(Table13[[#This Row],[Price]]*Table13[[#This Row],[Number of shares]],0) -> 699.6 | E25: {=_FV(Table13[[#This Row],[Company]],"Employees")} -> 320 | F25: {=_FV(Table13[[#This Row],[Company]],"Market cap",TRUE)} -> 1331444588 | G25: {=_FV(Table13[[#This Row],[Company]],"P/E",TRUE)} -> 0 | H25: {=_FV(Table13[[#This Row],[Company]],"Beta")} -> 2.934 | I25: =Table13[[#This Row],[MarketCap]]/Table13[[#This Row],[Employees]] -> 4160764.3 | J25: =Table13[[#This Row],[Value]] / SUM(Table13[Value]) -> 0.052274337
A27: (NASDAQ:AMZN*5+NASDAQ:TER*11+NASDAQ:ON*17+NASDAQ:NVTS*149+NASDAQ:INDI*220+NASDAQ:GOOG*6+NYSE:VPG*40+NYSE:ST*35+NASDAQ:OUST*33)/AMEX:SPY
A29: SemiConductors
A30: Company | B30: Price | C30: Number of shares | D30: Value | E30: Employees | F30: MarketCap | G30: P/E | H30: Beta | I30: Marketcap per employee | J30: Share of Portfolio
A31: #VALUE! | B31: {=_FV(A31,"Price")} -> 100.285 | C31: 5 | D31: =IFERROR(Table134[[#This Row],[Price]]*Table134[[#This Row],[Number of shares]],0) -> 501.425 | E31: {=_FV(Table134[[#This Row],[Company]],"Employees")} -> 1174 | F31: {=_FV(Table134[[#This Row],[Company]],"Market cap",TRUE)} -> 13725947779 | G31: {=_FV(Table134[[#This Row],[Company]],"P/E",TRUE)} -> 4497.0852 | H31: {=_FV(Table134[[#This Row],[Company]],"Beta")} -> 1.629 | I31: =Table134[[#This Row],[MarketCap]]/Table134[[#This Row],[Employees]] -> 11691608 | J31: =Table134[[#This Row],[Value]] / SUM(Table134[Value]) -> 0.0055398515
A32: #VALUE! | B32: {=_FV(A32,"Price")} -> 47.2901 | C32: 11 | D32: =IFERROR(Table134[[#This Row],[Price]]*Table134[[#This Row],[Number of shares]],0) -> 520.1911 | E32: {=_FV(Table134[[#This Row],[Company]],"Employees")} -> 85100 | F32: {=_FV(Table134[[#This Row],[Company]],"Market cap",TRUE)} -> 237444065001 | G32: {=_FV(Table134[[#This Row],[Company]],"P/E",TRUE)} -> 0 | H32: {=_FV(Table134[[#This Row],[Company]],"Beta")} -> 1.3543 | I32: =Table134[[#This Row],[MarketCap]]/Table134[[#This Row],[Employees]] -> 2790177 | J32: =Table134[[#This Row],[Value]] / SUM(Table134[Value]) -> 0.0057471834
A33: #VALUE! | B33: {=_FV(A33,"Price")} -> 93.075 | C33: 17 | D33: =IFERROR(Table134[[#This Row],[Price]]*Table134[[#This Row],[Number of shares]],0) -> 1582.275 | E33: {=_FV(Table134[[#This Row],[Company]],"Employees")} -> 791 | F33: {=_FV(Table134[[#This Row],[Company]],"Market cap",TRUE)} -> 10066936155 | G33: {=_FV(Table134[[#This Row],[Company]],"P/E",TRUE)} -> 44.0759 | H33: {=_FV(Table134[[#This Row],[Company]],"Beta")} -> 1.5964 | I33: =Table134[[#This Row],[MarketCap]]/Table134[[#This Row],[Employees]] -> 12726847 | J33: =Table134[[#This Row],[Value]] / SUM(Table134[Value]) -> 0.017481315
A34: #VALUE! | B34: {=_FV(A34,"Price")} -> 33.05 | C34: 149 | D34: =IFERROR(Table134[[#This Row],[Price]]*Table134[[#This Row],[Number of shares]],0) -> 4924.45 | E34: {=_FV(Table134[[#This Row],[Company]],"Employees")} -> 4060 | F34: {=_FV(Table134[[#This Row],[Company]],"Market cap",TRUE)} -> 6123864244 | G34: {=_FV(Table134[[#This Row],[Company]],"P/E",TRUE)} -> 0 | H34: {=_FV(Table134[[#This Row],[Company]],"Beta")} -> 1.6829 | I34: =Table134[[#This Row],[MarketCap]]/Table134[[#This Row],[Employees]] -> 1508340.9 | J34: =Table134[[#This Row],[Value]] / SUM(Table134[Value]) -> 0.054406385
A35: #VALUE! | B35: {=_FV(A35,"Price")} -> 131.635 | C35: 220 | D35: =IFERROR(Table134[[#This Row],[Price]]*Table134[[#This Row],[Number of shares]],0) -> 28959.7 | E35: {=_FV(Table134[[#This Row],[Company]],"Employees")} -> 52000 | F35: {=_FV(Table134[[#This Row],[Company]],"Market cap",TRUE)} -> 140454545000 | G35: {=_FV(Table134[[#This Row],[Company]],"P/E",TRUE)} -> 27.1951 | H35: {=_FV(Table134[[#This Row],[Company]],"Beta")} -> 1.2816 | I35: =Table134[[#This Row],[MarketCap]]/Table134[[#This Row],[Employees]] -> 2701048.9 | J35: =Table134[[#This Row],[Value]] / SUM(Table134[Value]) -> 0.31995301
A36: #VALUE! | B36: {=_FV(A36,"Price")} -> 374.08 | C36: 6 | D36: =IFERROR(Table134[[#This Row],[Price]]*Table134[[#This Row],[Number of shares]],0) -> 2244.48 | E36: {=_FV(Table134[[#This Row],[Company]],"Employees")} -> 35500 | F36: {=_FV(Table134[[#This Row],[Company]],"Market cap",TRUE)} -> 296873591392 | G36: {=_FV(Table134[[#This Row],[Company]],"P/E",TRUE)} -> 38.3283 | H36: {=_FV(Table134[[#This Row],[Company]],"Beta")} -> 1.5969 | I36: =Table134[[#This Row],[MarketCap]]/Table134[[#This Row],[Employees]] -> 8362636.4 | J36: =Table134[[#This Row],[Value]] / SUM(Table134[Value]) -> 0.024797499
A37: #VALUE! | B37: {=_FV(A37,"Price")} -> 40.73 | C37: 40 | D37: =IFERROR(Table134[[#This Row],[Price]]*Table134[[#This Row],[Number of shares]],0) -> 1629.2 | E37: {=_FV(Table134[[#This Row],[Company]],"Employees")} -> 136 | F37: {=_FV(Table134[[#This Row],[Company]],"Market cap",TRUE)} -> 1247451558 | G37: {=_FV(Table134[[#This Row],[Company]],"P/E",TRUE)} -> 0 | H37: {=_FV(Table134[[#This Row],[Company]],"Beta")} -> 2.2671 | I37: =Table134[[#This Row],[MarketCap]]/Table134[[#This Row],[Employees]] -> 9172437.9 | J37: =Table134[[#This Row],[Value]] / SUM(Table134[Value]) -> 0.017999753
A38: #VALUE! | B38: {=_FV(A38,"Price")} -> 1398.7901 | C38: 35 | D38: =IFERROR(Table134[[#This Row],[Price]]*Table134[[#This Row],[Number of shares]],0) -> 48957.654 | E38: {=_FV(Table134[[#This Row],[Company]],"Employees")} -> 43520 | F38: {=_FV(Table134[[#This Row],[Company]],"Market cap",TRUE)} -> 542937160097 | G38: {=_FV(Table134[[#This Row],[Company]],"P/E",TRUE)} -> 48.1909 | H38: {=_FV(Table134[[#This Row],[Company]],"Beta")} -> 1.8562 | I38: =Table134[[#This Row],[MarketCap]]/Table134[[#This Row],[Employees]] -> 12475578 | J38: =Table134[[#This Row],[Value]] / SUM(Table134[Value]) -> 0.54089471
A39: #VALUE! | B39: {=_FV(A39,"Price")} -> 198.83 | C39: 6 | D39: =IFERROR(Table134[[#This Row],[Price]]*Table134[[#This Row],[Number of shares]],0) -> 1192.98 | E39: {=_FV(Table134[[#This Row],[Company]],"Employees")} -> 32169 | F39: {=_FV(Table134[[#This Row],[Company]],"Market cap",TRUE)} -> 50242929307 | G39: {=_FV(Table134[[#This Row],[Company]],"P/E",TRUE)} -> 25.022 | H39: {=_FV(Table134[[#This Row],[Company]],"Beta")} -> 1.469 | I39: =Table134[[#This Row],[MarketCap]]/Table134[[#This Row],[Employees]] -> 1561843.1 | J39: =Table134[[#This Row],[Value]] / SUM(Table134[Value]) -> 0.0131803
A43: AI
A44: Company | B44: Price | C44: Number of shares | D44: Value | E44: Employees | F44: MarketCap | G44: P/E | H44: Beta | I44: Marketcap per employee | J44: Share of Portfolio
A45: #VALUE! | B45: {=_FV(A45,"Price")} -> 180.405 | C45: 5 | D45: =IFERROR(Table1345[[#This Row],[Price]]*Table1345[[#This Row],[Number of shares]],0) -> 902.025 | E45: {=_FV(Table1345[[#This Row],[Company]],"Employees")} -> 42000 | F45: {=_FV(Table1345[[#This Row],[Company]],"Market cap",TRUE)} -> 4383841500000 | G45: {=_FV(Table1345[[#This Row],[Company]],"P/E",TRUE)} -> 36.8038 | H45: {=_FV(Table1345[[#This Row],[Company]],"Beta")} -> 2.3397 | I45: =Table1345[[#This Row],[MarketCap]]/Table1345[[#This Row],[Employees]] -> 1.0437718e+08 | J45: =Table1345[[#This Row],[Value]] / SUM(Table1345[Value]) -> 0.0083909148
A46: #VALUE! | B46: {=_FV(A46,"Price")} -> 116.395 | C46: 11 | D46: =IFERROR(Table1345[[#This Row],[Price]]*Table1345[[#This Row],[Number of shares]],0) -> 1280.345 | E46: {=_FV(Table1345[[#This Row],[Company]],"Employees")} -> 1371 | F46: {=_FV(Table1345[[#This Row],[Company]],"Market cap",TRUE)} -> 29449913715 | G46: {=_FV(Table1345[[#This Row],[Company]],"P/E",TRUE)} -> 698.6495 | H46: {=_FV(Table1345[[#This Row],[Company]],"Beta")} -> -13.254 | I46: =Table1345[[#This Row],[MarketCap]]/Table1345[[#This Row],[Employees]] -> 21480608 | J46: =Table1345[[#This Row],[Value]] / SUM(Table1345[Value]) -> 0.011910164
A47: #VALUE! | B47: {=_FV(A47,"Price")} -> 23.8699 | C47: 17 | D47: =IFERROR(Table1345[[#This Row],[Price]]*Table1345[[#This Row],[Number of shares]],0) -> 405.7883 | E47: {=_FV(Table1345[[#This Row],[Company]],"Employees")} -> 6238 | F47: {=_FV(Table1345[[#This Row],[Company]],"Market cap",TRUE)} -> 14333442904 | G47: {=_FV(Table1345[[#This Row],[Company]],"P/E",TRUE)} -> 18.1963 | H47: {=_FV(Table1345[[#This Row],[Company]],"Beta")} -> 1.6309 | I47: =Table1345[[#This Row],[MarketCap]]/Table1345[[#This Row],[Employees]] -> 2297762.6 | J47: =Table1345[[#This Row],[Value]] / SUM(Table1345[Value]) -> 0.0037747679
...

Sheet Secondary Theme
A1: Secondary Theme Analysis
D2: =SUM(Table33[Target]) -> 0
A4: Secondary theme | B4: Stock Exposure | C4: Percentage of Stock Exposure | D4: Target | E4: Option Exposure | F4: Combined Exposure | G4: Percentage of Total
A5: Health Care: Value Care | B5: =SUMIF(Table19[Secondary theme],Table33[[#This Row],[Secondary theme]],Table19[Stock Exposure]) -> 5396.705 | C5: =Table33[[#This Row],[Stock Exposure]]/'Primary Theme'!$D$5 -> 0.041205242 | E5: =SUMIF(Table19[Secondary theme],Table33[[#This Row],[Secondary theme]],Table19[Option Exposure]) -> 0 | F5: =Table33[[#This Row],[Stock Exposure]]+Table33[[#This Row],[Option Exposure]] -> 5396.705 | G5: =Table33[[#This Row],[Combined Exposure]]/'Primary Theme'!$D$4 -> 0.034015973
A6: Technology | B6: =SUMIF(Table19[Secondary theme],Table33[[#This Row],[Secondary theme]],Table19[Stock Exposure]) -> 8853.1435 | C6: =Table33[[#This Row],[Stock Exposure]]/'Primary Theme'!$D$5 -> 0.067596046 | E6: =SUMIF(Table19[Secondary theme],Table33[[#This Row],[Secondary theme]],Table19[Option Exposure]) -> 0 | F6: =Table33[[#This Row],[Stock Exposure]]+Table33[[#This Row],[Option Exposure]] -> 8853.1435 | G6: =Table33[[#This Row],[Combined Exposure]]/'Primary Theme'!$D$4 -> 0.055802252
A7: Industrials | B7: =SUMIF(Table19[Secondary theme],Table33[[#This Row],[Secondary theme]],Table19[Stock Exposure]) -> 15939.239 | C7: =Table33[[#This Row],[Stock Exposure]]/'Primary Theme'!$D$5 -> 0.12170023 | E7: =SUMIF(Table19[Secondary theme],Table33[[#This Row],[Secondary theme]],Table19[Option Exposure]) -> 0 | F7: =Table33[[#This Row],[Stock Exposure]]+Table33[[#This Row],[Option Exposure]] -> 15939.239 | G7: =Table33[[#This Row],[Combined Exposure]]/'Primary Theme'!$D$4 -> 0.10046663
A8: Crypto | B8: =SUMIF(Table19[Secondary theme],Table33[[#This Row],[Secondary theme]],Table19[Stock Exposure]) -> 1843.7925 | C8: =Table33[[#This Row],[Stock Exposure]]/'Primary Theme'!$D$5 -> 0.014077834 | E8: =SUMIF(Table19[Secondary theme],Table33[[#This Row],[Secondary theme]],Table19[Option Exposure]) -> 0 | F8: =Table33[[#This Row],[Stock Exposure]]+Table33[[#This Row],[Option Exposure]] -> 1843.7925 | G8: =Table33[[#This Row],[Combined Exposure]]/'Primary Theme'!$D$4 -> 0.011621609
A9: Drone | B9: =SUMIF(Table19[Secondary theme],Table33[[#This Row],[Secondary theme]],Table19[Stock Exposure]) -> 4265.405 | C9: =Table33[[#This Row],[Stock Exposure]]/'Primary Theme'!$D$5 -> 0.032567473 | E9: =SUMIF(Table19[Secondary theme],Table33[[#This Row],[Secondary theme]],Table19[Option Exposure]) -> 0 | F9: =Table33[[#This Row],[Stock Exposure]]+Table33[[#This Row],[Option Exposure]] -> 4265.405 | G9: =Table33[[#This Row],[Combined Exposure]]/'Primary Theme'!$D$4 -> 0.026885276
A10: Health Care | B10: =SUMIF(Table19[Secondary theme],Table33[[#This Row],[Secondary theme]],Table19[Stock Exposure]) -> 1911.8083 | C10: =Table33[[#This Row],[Stock Exposure]]/'Primary Theme'!$D$5 -> 0.014597152 | E10: =SUMIF(Table19[Secondary theme],Table33[[#This Row],[Secondary theme]],Table19[Option Exposure]) -> 0 | F10: =Table33[[#This Row],[Stock Exposure]]+Table33[[#This Row],[Option Exposure]] -> 1911.8083 | G10: =Table33[[#This Row],[Combined Exposure]]/'Primary Theme'!$D$4 -> 0.012050319
A11: Energy | B11: =SUMIF(Table19[Secondary theme],Table33[[#This Row],[Secondary theme]],Table19[Stock Exposure]) -> 18756.008 | C11: =Table33[[#This Row],[Stock Exposure]]/'Primary Theme'!$D$5 -> 0.14320699 | E11: =SUMIF(Table19[Secondary theme],Table33[[#This Row],[Secondary theme]],Table19[Option Exposure]) -> 4766.1976 | F11: =Table33[[#This Row],[Stock Exposure]]+Table33[[#This Row],[Option Exposure]] -> 23522.206 | G11: =Table33[[#This Row],[Combined Exposure]]/'Primary Theme'!$D$4 -> 0.14826282
A12: AI | B12: =SUMIF(Table19[Secondary theme],Table33[[#This Row],[Secondary theme]],Table19[Stock Exposure]) -> 15131.783 | C12: =Table33[[#This Row],[Stock Exposure]]/'Primary Theme'!$D$5 -> 0.11553509 | E12: =SUMIF(Table19[Secondary theme],Table33[[#This Row],[Secondary theme]],Table19[Option Exposure]) -> 0 | F12: =Table33[[#This Row],[Stock Exposure]]+Table33[[#This Row],[Option Exposure]] -> 15131.783 | G12: =Table33[[#This Row],[Combined Exposure]]/'Primary Theme'!$D$4 -> 0.095377146
A13: Auto | B13: =SUMIF(Table19[Secondary theme],Table33[[#This Row],[Secondary theme]],Table19[Stock Exposure]) -> 3718.09 | C13: =Table33[[#This Row],[Stock Exposure]]/'Primary Theme'!$D$5 -> 0.028388581 | E13: =SUMIF(Table19[Secondary theme],Table33[[#This Row],[Secondary theme]],Table19[Option Exposure]) -> 0 | F13: =Table33[[#This Row],[Stock Exposure]]+Table33[[#This Row],[Option Exposure]] -> 3718.09 | G13: =Table33[[#This Row],[Combined Exposure]]/'Primary Theme'!$D$4 -> 0.023435494
A14: Semiconductor | B14: =SUMIF(Table19[Secondary theme],Table33[[#This Row],[Secondary theme]],Table19[Stock Exposure]) -> 20302.661 | C14: =Table33[[#This Row],[Stock Exposure]]/'Primary Theme'!$D$5 -> 0.15501608 | E14: =SUMIF(Table19[Secondary theme],Table33[[#This Row],[Secondary theme]],Table19[Option Exposure]) -> 7135.6592 | F14: =Table33[[#This Row],[Stock Exposure]]+Table33[[#This Row],[Option Exposure]] -> 27438.32 | G14: =Table33[[#This Row],[Combined Exposure]]/'Primary Theme'!$D$4 -> 0.17294649
A15: Robotics | B15: =SUMIF(Table19[Secondary theme],Table33[[#This Row],[Secondary theme]],Table19[Stock Exposure]) -> 786.93 | C15: =Table33[[#This Row],[Stock Exposure]]/'Primary Theme'!$D$5 -> 0.0060084146 | E15: =SUMIF(Table19[Secondary theme],Table33[[#This Row],[Secondary theme]],Table19[Option Exposure]) -> 0 | F15: =Table33[[#This Row],[Stock Exposure]]+Table33[[#This Row],[Option Exposure]] -> 786.93 | G15: =Table33[[#This Row],[Combined Exposure]]/'Primary Theme'!$D$4 -> 0.0049600987
A16: Financials | B16: =SUMIF(Table19[Secondary theme],Table33[[#This Row],[Secondary theme]],Table19[Stock Exposure]) -> 0 | C16: =Table33[[#This Row],[Stock Exposure]]/'Primary Theme'!$D$5 -> 0 | E16: =SUMIF(Table19[Secondary theme],Table33[[#This Row],[Secondary theme]],Table19[Option Exposure]) -> 0 | F16: =Table33[[#This Row],[Stock Exposure]]+Table33[[#This Row],[Option Exposure]] -> 0 | G16: =Table33[[#This Row],[Combined Exposure]]/'Primary Theme'!$D$4 -> 0
... A93: Semiconductor: Materials | B93: =SUMIF(Table19[Secondary theme],Table33[[#This Row],[Secondary theme]],Table19[Stock Exposure]) -> 1413.798 | C93: =Table33[[#This Row],[Stock Exposure]]/'Primary Theme'!$D$5 -> 0.010794714 | E93: =SUMIF(Table19[Secondary theme],Table33[[#This Row],[Secondary theme]],Table19[Option Exposure]) -> 0 | F93: =Table33[[#This Row],[Stock Exposure]]+Table33[[#This Row],[Option Exposure]] -> 1413.798 | G93: =Table33[[#This Row],[Combined Exposure]]/'Primary Theme'!$D$4 -> 0.0089113106

Sheet Option Report
A1: Assets | B1: Ticker | C1: Asset type | D1: 52 week low | E1: Dis to 52 week low | F1: Current Price | G1: Dis to 52w high | H1: 52 week high | I1: Bullish | J1: Bearish | K1: Next Earning | L1: From Support | M1: From Resistance | N1: Latest Update | O1: Theme | P1: Signal
A2: {=_xlfn.UNIQUE(Table41[Asset Name],FALSE,FALSE)} -> #VALUE! | B2: =VLOOKUP(A2,Table41[#All],2,FALSE) -> MAG | C2: =VLOOKUP(A2,Table41[#All],20,FALSE) -> Stock | D2: {=_FV(A2,"52 week low",TRUE)} -> 11.72 | E2: =(Table44[[#This Row],[Current Price]]-Table44[[#This Row],[52 week low]])/Table44[[#This Row],[52 week low]] -> 1.087884 | F2: =VLOOKUP(A2,Table41[#All],15,FALSE) -> 24.47 | G2: =(Table44[[#This Row],[52 week high]]-Table44[[#This Row],[Current Price]])/Table44[[#This Row],[Current Price]] -> 0.025337148 | H2: {=_FV(A2,"52 week high",TRUE)} -> 25.09 | I2: =VLOOKUP(A2,Table41[#All],17,FALSE) -> FALSE | J2: =VLOOKUP(A2,Table41[#All],18,FALSE) -> TRUE | K2: =VLOOKUP(A2,Table41[#All],21,FALSE) -> 45588 | L2: =VLOOKUP(A2,Table41[#All],26,FALSE) -> 0.9576 | M2: =VLOOKUP(A2,Table41[#All],27,FALSE) -> 0.63133333 | N2: =HLOOKUP(Table44[[#This Row],[Theme]],Table46[#All],2,FALSE) -> 45567 | O2: =VLOOKUP(A2,Table41[#All],22,FALSE) -> Gold and Silver | P2: =VLOOKUP(A2,Table41[#All],25,FALSE) -> 🔻
A3: #VALUE! | B3: =VLOOKUP(A3,Table41[#All],2,FALSE) -> CLS | C3: =VLOOKUP(A3,Table41[#All],20,FALSE) -> Stock | D3: {=_FV(A3,"52 week low",TRUE)} -> 58.05 | E3: =(Table44[[#This Row],[Current Price]]-Table44[[#This Row],[52 week low]])/Table44[[#This Row],[52 week low]] -> 4.2944014 | F3: =VLOOKUP(A3,Table41[#All],15,FALSE) -> 307.34 | G3: =(Table44[[#This Row],[52 week high]]-Table44[[#This Row],[Current Price]])/Table44[[#This Row],[Current Price]] -> 0.18240385 | H3: {=_FV(A3,"52 week high",TRUE)} -> 363.4 | I3: =VLOOKUP(A3,Table41[#All],17,FALSE) -> FALSE | J3: =VLOOKUP(A3,Table41[#All],18,FALSE) -> TRUE | K3: =VLOOKUP(A3,Table41[#All],21,FALSE) -> 45588 | L3: =VLOOKUP(A3,Table41[#All],26,FALSE) -> 0 | M3: =VLOOKUP(A3,Table41[#All],27,FALSE) -> 2.84175 | N3: =HLOOKUP(Table44[[#This Row],[Theme]],Table46[#All],2,FALSE) -> 45587 | O3: =VLOOKUP(A3,Table41[#All],22,FALSE) -> AI | P3: =VLOOKUP(A3,Table41[#All],25,FALSE) -> 🔻
A4: #VALUE! | B4: =VLOOKUP(A4,Table41[#All],2,FALSE) -> SNAP | C4: =VLOOKUP(A4,Table41[#All],20,FALSE) -> Stock | D4: {=_FV(A4,"52 week low",TRUE)} -> 4.31 | E4: =(Table44[[#This Row],[Current Price]]-Table44[[#This Row],[52 week low]])/Table44[[#This Row],[52 week low]] -> 0.056844548 | F4: =VLOOKUP(A4,Table41[#All],15,FALSE) -> 4.555 | G4: =(Table44[[#This Row],[52 week high]]-Table44[[#This Row],[Current Price]])/Table44[[#This Row],[Current Price]] -> 1.2854007 | H4: {=_FV(A4,"52 week high",TRUE)} -> 10.41 | I4: =VLOOKUP(A4,Table41[#All],17,FALSE) -> TRUE | J4: =VLOOKUP(A4,Table41[#All],18,FALSE) -> FALSE | K4: =VLOOKUP(A4,Table41[#All],21,FALSE) -> 0 | L4: =VLOOKUP(A4,Table41[#All],26,FALSE) -> -0.5445 | M4: =VLOOKUP(A4,Table41[#All],27,FALSE) -> -0.67464286 | N4: =HLOOKUP(Table44[[#This Row],[Theme]],Table46[#All],2,FALSE) -> 45594 | O4: =VLOOKUP(A4,Table41[#All],22,FALSE) -> Technology | P4: =VLOOKUP(A4,Table41[#All],25,FALSE) -> ✅
A5: #VALUE! | B5: =VLOOKUP(A5,Table41[#All],2,FALSE) -> SPY | C5: =VLOOKUP(A5,Table41[#All],20,FALSE) -> ETF | D5: {=_FV(A5,"52 week low",TRUE)} -> 481.8 | E5: =(Table44[[#This Row],[Current Price]]-Table44[[#This Row],[52 week low]])/Table44[[#This Row],[52 week low]] -> 0.36693649 | F5: =VLOOKUP(A5,Table41[#All],15,FALSE) -> 658.59 | G5: =(Table44[[#This Row],[52 week high]]-Table44[[#This Row],[Current Price]])/Table44[[#This Row],[Current Price]] -> 0.059597018 | H5: {=_FV(A5,"52 week high",TRUE)} -> 697.84 | I5: =VLOOKUP(A5,Table41[#All],17,FALSE) -> FALSE | J5: =VLOOKUP(A5,Table41[#All],18,FALSE) -> TRUE | K5: =VLOOKUP(A5,Table41[#All],21,FALSE) -> 0 | L5: =VLOOKUP(A5,Table41[#All],26,FALSE) -> 0.17605357 | M5: =VLOOKUP(A5,Table41[#All],27,FALSE) -> 0.11625424 | N5: =HLOOKUP(Table44[[#This Row],[Theme]],Table46[#All],2,FALSE) -> 45564 | O5: =VLOOKUP(A5,Table41[#All],22,FALSE) -> Market | P5: =VLOOKUP(A5,Table41[#All],25,FALSE) -> 🔻
A6: #VALUE! | B6: =VLOOKUP(A6,Table41[#All],2,FALSE) -> RMBS | C6: =VLOOKUP(A6,Table41[#All],20,FALSE) -> Stock | D6: {=_FV(A6,"52 week low",TRUE)} -> 40.12 | E6: =(Table44[[#This Row],[Current Price]]-Table44[[#This Row],[52 week low]])/Table44[[#This Row],[52 week low]] -> 1.3199153 | F6: =VLOOKUP(A6,Table41[#All],15,FALSE) -> 93.075 | G6: =(Table44[[#This Row],[52 week high]]-Table44[[#This Row],[Current Price]])/Table44[[#This Row],[Current Price]] -> 0.45850121 | H6: {=_FV(A6,"52 week high",TRUE)} -> 135.75 | I6: =VLOOKUP(A6,Table41[#All],17,FALSE) -> FALSE | J6: =VLOOKUP(A6,Table41[#All],18,FALSE) -> TRUE | K6: =VLOOKUP(A6,Table41[#All],21,FALSE) -> 45593 | L6: =VLOOKUP(A6,Table41[#All],26,FALSE) -> 0.95947368 | M6: =VLOOKUP(A6,Table41[#All],27,FALSE) -> 0.77285714 | N6: =HLOOKUP(Table44[[#This Row],[Theme]],Table46[#All],2,FALSE) -> 45580 | O6: =VLOOKUP(A6,Table41[#All],22,FALSE) -> Semiconductor | P6: =VLOOKUP(A6,Table41[#All],25,FALSE) -> 🔻
A7: #VALUE! | B7: =VLOOKUP(A7,Table41[#All],2,FALSE) -> AG | C7: =VLOOKUP(A7,Table41[#All],20,FALSE) -> Stock | D7: {=_FV(A7,"52 week low",TRUE)} -> 5.185 | E7: =(Table44[[#This Row],[Current Price]]-Table44[[#This Row],[52 week low]])/Table44[[#This Row],[52 week low]] -> 3.0086789 | F7: =VLOOKUP(A7,Table41[#All],15,FALSE) -> 20.785 | G7: =(Table44[[#This Row],[52 week high]]-Table44[[#This Row],[Current Price]])/Table44[[#This Row],[Current Price]] -> 0.54125571 | H7: {=_FV(A7,"52 week high",TRUE)} -> 32.035 | I7: =VLOOKUP(A7,Table41[#All],17,FALSE) -> FALSE | J7: =VLOOKUP(A7,Table41[#All],18,FALSE) -> TRUE | K7: =VLOOKUP(A7,Table41[#All],21,FALSE) -> 45603 | L7: =VLOOKUP(A7,Table41[#All],26,FALSE) -> 3.157 | M7: =VLOOKUP(A7,Table41[#All],27,FALSE) -> 1.9692857 | N7: =HLOOKUP(Table44[[#This Row],[Theme]],Table46[#All],2,FALSE) -> 45567 | O7: =VLOOKUP(A7,Table41[#All],22,FALSE) -> Gold and Silver | P7: =VLOOKUP(A7,Table41[#All],25,FALSE) -> 🔻
A8: #VALUE! | B8: =VLOOKUP(A8,Table41[#All],2,FALSE) -> VIX | C8: =VLOOKUP(A8,Table41[#All],20,FALSE) -> Index | D8: {=_FV(A8,"52 week low",TRUE)} -> 13.38 | E8: =(Table44[[#This Row],[Current Price]]-Table44[[#This Row],[52 week low]])/Table44[[#This Row],[52 week low]] -> 0.89312407 | F8: =VLOOKUP(A8,Table41[#All],15,FALSE) -> 25.33 | G8: =(Table44[[#This Row],[52 week high]]-Table44[[#This Row],[Current Price]])/Table44[[#This Row],[Current Price]] -> 1.373865 | H8: {=_FV(A8,"52 week high",TRUE)} -> 60.13 | I8: =VLOOKUP(A8,Table41[#All],17,FALSE) -> FALSE | J8: =VLOOKUP(A8,Table41[#All],18,FALSE) -> TRUE | K8: =VLOOKUP(A8,Table41[#All],21,FALSE) -> 0 | L8: =VLOOKUP(A8,Table41[#All],26,FALSE) -> 0 | M8: =VLOOKUP(A8,Table41[#All],27,FALSE) -> 0.2665 | N8: =HLOOKUP(Table44[[#This Row],[Theme]],Table46[#All],2,FALSE) -> 45564 | O8: =VLOOKUP(A8,Table41[#All],22,FALSE) -> Market | P8: =VLOOKUP(A8,Table41[#All],25,FALSE) -> 🔻
A9: #VALUE! | B9: =VLOOKUP(A9,Table41[#All],2,FALSE) -> CSCO | C9: =VLOOKUP(A9,Table41[#All],20,FALSE) -> Stock | D9: {=_FV(A9,"52 week low",TRUE)} -> 52.11 | E9: =(Table44[[#This Row],[Current Price]]-Table44[[#This Row],[52 week low]])/Table44[[#This Row],[52 week low]] -> 0.58558818 | F9: =VLOOKUP(A9,Table41[#All],15,FALSE) -> 82.625 | G9: =(Table44[[#This Row],[52 week high]]-Table44[[#This Row],[Current Price]])/Table44[[#This Row],[Current Price]] -> 0.067291982 | H9: {=_FV(A9,"52 week high",TRUE)} -> 88.185 | I9: =VLOOKUP(A9,Table41[#All],17,FALSE) -> FALSE | J9: =VLOOKUP(A9,Table41[#All],18,FALSE) -> TRUE | K9: =VLOOKUP(A9,Table41[#All],21,FALSE) -> 45609 | L9: =VLOOKUP(A9,Table41[#All],26,FALSE) -> 0.6525 | M9: =VLOOKUP(A9,Table41[#All],27,FALSE) -> 0.43695652 | N9: =HLOOKUP(Table44[[#This Row],[Theme]],Table46[#All],2,FALSE) -> 45602 | O9: =VLOOKUP(A9,Table41[#All],22,FALSE) -> Connectivity | P9: =VLOOKUP(A9,Table41[#All],25,FALSE) -> 🔻
A10: #VALUE! | B10: =VLOOKUP(A10,Table41[#All],2,FALSE) -> FNV | C10: =VLOOKUP(A10,Table41[#All],20,FALSE) -> Stock | D10: {=_FV(A10,"52 week low",TRUE)} -> 140.03 | E10: =(Table44[[#This Row],[Current Price]]-Table44[[#This Row],[52 week low]])/Table44[[#This Row],[52 week low]] -> 0.68013997 | F10: =VLOOKUP(A10,Table41[#All],15,FALSE) -> 235.27 | G10: =(Table44[[#This Row],[52 week high]]-Table44[[#This Row],[Current Price]])/Table44[[#This Row],[Current Price]] -> 0.21422196 | H10: {=_FV(A10,"52 week high",TRUE)} -> 285.67 | I10: =VLOOKUP(A10,Table41[#All],17,FALSE) -> FALSE | J10: =VLOOKUP(A10,Table41[#All],18,FALSE) -> TRUE | K10: =VLOOKUP(A10,Table41[#All],21,FALSE) -> 45610 | L10: =VLOOKUP(A10,Table41[#All],26,FALSE) -> 0.96058333 | M10: =VLOOKUP(A10,Table41[#All],27,FALSE) -> 0.80976923 | N10: =HLOOKUP(Table44[[#This Row],[Theme]],Table46[#All],2,FALSE) -> 45567 | O10: =VLOOKUP(A10,Table41[#All],22,FALSE) -> Gold and Silver | P10: =VLOOKUP(A10,Table41[#All],25,FALSE) -> 🔻
A11: #VALUE! | B11: =VLOOKUP(A11,Table41[#All],2,FALSE) -> URA | C11: =VLOOKUP(A11,Table41[#All],20,FALSE) -> ETF | D11: {=_FV(A11,"52 week low",TRUE)} -> 19.5 | E11: =(Table44[[#This Row],[Current Price]]-Table44[[#This Row],[52 week low]])/Table44[[#This Row],[52 week low]] -> 1.5595846 | F11: =VLOOKUP(A11,Table41[#All],15,FALSE) -> 49.9119 | G11: =(Table44[[#This Row],[52 week high]]-Table44[[#This Row],[Current Price]])/Table44[[#This Row],[Current Price]] -> 0.24779862 | H11: {=_FV(A11,"52 week high",TRUE)} -> 62.28 | I11: =VLOOKUP(A11,Table41[#All],17,FALSE) -> FALSE | J11: =VLOOKUP(A11,Table41[#All],18,FALSE) -> TRUE | K11: =VLOOKUP(A11,Table41[#All],21,FALSE) -> 0 | L11: =VLOOKUP(A11,Table41[#All],26,FALSE) -> 1.3767571 | M11: =VLOOKUP(A11,Table41[#All],27,FALSE) -> 0.66373 | N11: =HLOOKUP(Table44[[#This Row],[Theme]],Table46[#All],2,FALSE) -> 45569 | O11: =VLOOKUP(A11,Table41[#All],22,FALSE) -> Nuclear | P11: =VLOOKUP(A11,Table41[#All],25,FALSE) -> 🔻
A12: #VALUE! | B12: =VLOOKUP(A12,Table41[#All],2,FALSE) -> SMR | C12: =VLOOKUP(A12,Table41[#All],20,FALSE) -> Stock | D12: {=_FV(A12,"52 week low",TRUE)} -> 11.08 | E12: =(Table44[[#This Row],[Current Price]]-Table44[[#This Row],[52 week low]])/Table44[[#This Row],[52 week low]] -> 0.067680505 | F12: =VLOOKUP(A12,Table41[#All],15,FALSE) -> 11.8299 | G12: =(Table44[[#This Row],[52 week high]]-Table44[[#This Row],[Current Price]])/Table44[[#This Row],[Current Price]] -> 3.8538027 | H12: {=_FV(A12,"52 week high",TRUE)} -> 57.42 | I12: =VLOOKUP(A12,Table41[#All],17,FALSE) -> TRUE | J12: =VLOOKUP(A12,Table41[#All],18,FALSE) -> FALSE | K12: =VLOOKUP(A12,Table41[#All],21,FALSE) -> 45603 | L12: =VLOOKUP(A12,Table41[#All],26,FALSE) -> -0.26063125 | M12: =VLOOKUP(A12,Table41[#All],27,FALSE) -> -0.408505 | N12: =HLOOKUP(Table44[[#This Row],[Theme]],Table46[#All],2,FALSE) -> 45569 | O12: =VLOOKUP(A12,Table41[#All],22,FALSE) -> Nuclear | P12: =VLOOKUP(A12,Table41[#All],25,FALSE) -> ✅
A13: #VALUE! | B13: =VLOOKUP(A13,Table41[#All],2,FALSE) -> GM | C13: =VLOOKUP(A13,Table41[#All],20,FALSE) -> Stock | D13: {=_FV(A13,"52 week low",TRUE)} -> 41.6 | E13: =(Table44[[#This Row],[Current Price]]-Table44[[#This Row],[52 week low]])/Table44[[#This Row],[52 week low]] -> 0.87127404 | F13: =VLOOKUP(A13,Table41[#All],15,FALSE) -> 77.845 | G13: =(Table44[[#This Row],[52 week high]]-Table44[[#This Row],[Current Price]])/Table44[[#This Row],[Current Price]] -> 0.12557004 | H13: {=_FV(A13,"52 week high",TRUE)} -> 87.62 | I13: =VLOOKUP(A13,Table41[#All],17,FALSE) -> FALSE | J13: =VLOOKUP(A13,Table41[#All],18,FALSE) -> TRUE | K13: =VLOOKUP(A13,Table41[#All],21,FALSE) -> 0 | L13: =VLOOKUP(A13,Table41[#All],26,FALSE) -> 0 | M13: =VLOOKUP(A13,Table41[#All],27,FALSE) -> 0.5569 | N13: =HLOOKUP(Table44[[#This Row],[Theme]],Table46[#All],2,FALSE) -> 45575 | O13: =VLOOKUP(A13,Table41[#All],22,FALSE) -> Auto | P13: =VLOOKUP(A13,Table41[#All],25,FALSE) -> 🔻
A14: #VALUE! | B14: =VLOOKUP(A14,Table41[#All],2,FALSE) -> GDX | C14: =VLOOKUP(A14,Table41[#All],20,FALSE) -> ETF | D14: {=_FV(A14,"52 week low",TRUE)} -> 40.26 | E14: =(Table44[[#This Row],[Current Price]]-Table44[[#This Row],[52 week low]])/Table44[[#This Row],[52 week low]] -> 1.1624441 | F14: =VLOOKUP(A14,Table41[#All],15,FALSE) -> 87.06 | G14: =(Table44[[#This Row],[52 week high]]-Table44[[#This Row],[Current Price]])/Table44[[#This Row],[Current Price]] -> 0.34591087 | H14: {=_FV(A14,"52 week high",TRUE)} -> 117.175 | I14: =VLOOKUP(A14,Table41[#All],17,FALSE) -> FALSE | J14: =VLOOKUP(A14,Table41[#All],18,FALSE) -> TRUE | K14: =VLOOKUP(A14,Table41[#All],21,FALSE) -> 0 | L14: =VLOOKUP(A14,Table41[#All],26,FALSE) -> 1.2323077 | M14: =VLOOKUP(A14,Table41[#All],27,FALSE) -> 1.1765 | N14: =HLOOKUP(Table44[[#This Row],[Theme]],Table46[#All],2,FALSE) -> 45567 | O14: =VLOOKUP(A14,Table41[#All],22,FALSE) -> Gold and Silver | P14: =VLOOKUP(A14,Table41[#All],25,FALSE) -> 🔻
... A122: #VALUE! | B122: =VLOOKUP(A122,Table41[#All],2,FALSE) -> ACHC | C122: =VLOOKUP(A122,Table41[#All],20,FALSE) -> Stock | D122: {=_FV(A122,"52 week low",TRUE)} -> 11.43 | E122: =(Table44[[#This Row],[Current Price]]-Table44[[#This Row],[52 week low]])/Table44[[#This Row],[52 week low]] -> 1.0804899 | F122: =VLOOKUP(A122,Table41[#All],15,FALSE) -> 23.78 | G122: =(Table44[[#This Row],[52 week high]]-Table44[[#This Row],[Current Price]])/Table44[[#This Row],[Current Price]] -> 0.30529857 | H122: {=_FV(A122,"52 week high",TRUE)} -> 31.04 | I122: =VLOOKUP(A122,Table41[#All],17,FALSE) -> FALSE | J122: =VLOOKUP(A122,Table41[#All],18,FALSE) -> TRUE | K122: =VLOOKUP(A122,Table41[#All],21,FALSE) -> 0 | L122: =VLOOKUP(A122,Table41[#All],26,FALSE) -> 0 | M122: =VLOOKUP(A122,Table41[#All],27,FALSE) -> #DIV/0! | N122: =HLOOKUP(Table44[[#This Row],[Theme]],Table46[#All],2,FALSE) -> 45567 | O122: =VLOOKUP(A122,Table41[#All],22,FALSE) -> Health Care | P122: =VLOOKUP(A122,Table41[#All],25,FALSE) -> 🔻

Sheet Primary Theme
A1: Primary Theme Analysis
B3: Primary | C3: Secondary | D3: From Equity Portfolio
A4: Total Exposure | B4: =SUM(Table21[[#All],[Combined Exposure]]) -> 156139.91 | C4: =C5+C6 -> 159591.92 | D4: =EquityPortfolio!B8 -> 158652.08
A5: Stock Exposure | B5: =SUM(Table21[[#All],[Stock Exposure]]) -> 128459.15 | C5: =SUM(Table33[[#All],[Stock Exposure]]) -> 131911.16 | D5: =EquityPortfolio!B9 -> 130971.32
A6: Option Exposure | B6: =SUM(Table21[[#All],[Option Exposure]]) -> 27680.762 | C6: =SUM(Table33[Option Exposure]) -> 27680.762 | D6: =EquityPortfolio!B10 -> 27680.762
D8: =SUM(Table21[Percentage of Stock Exposure]) -> 0.98081893 | E8: =SUM(Table21[Target]) -> 1.02 | H8: =SUM(Table21[Realized Profit]) -> 12649.953 | I8: =SUM(Table21[Unrealized Profit]) -> 33713.259
A10: Primary theme | B10: Stock Exposure | C10: Cost basis | D10: Percentage of Stock Exposure | E10: Target | F10: Option Exposure | G10: Combined Exposure | H10: Percentage of Total | I10: Realized Profit | J10: Unrealized Profit | K10: Percentage in profit | L10: Over allocated
A11: AI | B11: =SUMIF(Table19[[#All],[Primary theme]],Table21[[#This Row],[Primary theme]],Table19[[#All],[Stock Exposure]]) -> 25215.576 | C11: =SUMIF(Table19[[#All],[Primary theme]],Table21[[#This Row],[Primary theme]],Table19[[#All],[Cost of current position]]) -> 18075.068 | D11: =Table21[[#This Row],[Stock Exposure]]/$D$5 -> 0.19252746 | E11: 0.1 | F11: =SUMIF(Table19[[#All],[Primary theme]],Table21[[#This Row],[Primary theme]],Table19[[#All],[Option Exposure]]) -> 7135.6592 | G11: =Table21[[#This Row],[Option Exposure]]+Table21[[#This Row],[Stock Exposure]] -> 32351.235 | H11: =Table21[[#This Row],[Combined Exposure]]/$D$4 -> 0.20391308 | I11: =SUMIF(Table19[Primary theme],Table21[[#This Row],[Primary theme]],Table19[Realized Profit]) -> 1333.1755 | J11: =SUMIF(Table19[Primary theme],Table21[[#This Row],[Primary theme]],Table19[Unrealized Profit]) -> 7140.5085 | K11: =IFERROR(Table21[[#This Row],[Unrealized Profit]]/Table21[[#This Row],[Cost basis]],"") -> 0.39504741 | L11: =IF(Table21[[#This Row],[Percentage of Stock Exposure]]>Table21[[#This Row],[Target]],TRUE,FALSE) -> TRUE
A12: Health Care | B12: =SUMIF(Table19[[#All],[Primary theme]],Table21[[#This Row],[Primary theme]],Table19[[#All],[Stock Exposure]]) -> 10338.291 | C12: =SUMIF(Table19[[#All],[Primary theme]],Table21[[#This Row],[Primary theme]],Table19[[#All],[Cost of current position]]) -> 12782.789 | D12: =Table21[[#This Row],[Stock Exposure]]/$D$5 -> 0.078935535 | E12: 0.2 | F12: =SUMIF(Table19[[#All],[Primary theme]],Table21[[#This Row],[Primary theme]],Table19[[#All],[Option Exposure]]) -> 0 | G12: =Table21[[#This Row],[Option Exposure]]+Table21[[#This Row],[Stock Exposure]] -> 10338.291 | H12: =Table21[[#This Row],[Combined Exposure]]/$D$4 -> 0.065163287 | I12: =SUMIF(Table19[Primary theme],Table21[[#This Row],[Primary theme]],Table19[Realized Profit]) -> -6397.8231 | J12: =SUMIF(Table19[Primary theme],Table21[[#This Row],[Primary theme]],Table19[Unrealized Profit]) -> -2444.4974 | K12: =IFERROR(Table21[[#This Row],[Unrealized Profit]]/Table21[[#This Row],[Cost basis]],"") -> -0.1912335 | L12: =IF(Table21[[#This Row],[Percentage of Stock Exposure]]>Table21[[#This Row],[Target]],TRUE,FALSE) -> FALSE
A13: Energy | B13: =SUMIF(Table19[[#All],[Primary theme]],Table21[[#This Row],[Primary theme]],Table19[[#All],[Stock Exposure]]) -> 22092.808 | C13: =SUMIF(Table19[[#All],[Primary theme]],Table21[[#This Row],[Primary theme]],Table19[[#All],[Cost of current position]]) -> 15400.002 | D13: =Table21[[#This Row],[Stock Exposure]]/$D$5 -> 0.16868432 | E13: 0.1 | F13: =SUMIF(Table19[[#All],[Primary theme]],Table21[[#This Row],[Primary theme]],Table19[[#All],[Option Exposure]]) -> 4766.1976 | G13: =Table21[[#This Row],[Option Exposure]]+Table21[[#This Row],[Stock Exposure]] -> 26859.006 | H13: =Table21[[#This Row],[Combined Exposure]]/$D$4 -> 0.16929501 | I13: =SUMIF(Table19[Primary theme],Table21[[#This Row],[Primary theme]],Table19[Realized Profit]) -> -2134.8569 | J13: =SUMIF(Table19[Primary theme],Table21[[#This Row],[Primary theme]],Table19[Unrealized Profit]) -> 6692.8064 | K13: =IFERROR(Table21[[#This Row],[Unrealized Profit]]/Table21[[#This Row],[Cost basis]],"") -> 0.43459777 | L13: =IF(Table21[[#This Row],[Percentage of Stock Exposure]]>Table21[[#This Row],[Target]],TRUE,FALSE) -> TRUE
A14: Semiconductor | B14: =SUMIF(Table19[[#All],[Primary theme]],Table21[[#This Row],[Primary theme]],Table19[[#All],[Stock Exposure]]) -> 17535.553 | C14: =SUMIF(Table19[[#All],[Primary theme]],Table21[[#This Row],[Primary theme]],Table19[[#All],[Cost of current position]]) -> 12052.078 | D14: =Table21[[#This Row],[Stock Exposure]]/$D$5 -> 0.13388849 | E14: 0.03 | F14: =SUMIF(Table19[[#All],[Primary theme]],Table21[[#This Row],[Primary theme]],Table19[[#All],[Option Exposure]]) -> 0 | G14: =Table21[[#This Row],[Option Exposure]]+Table21[[#This Row],[Stock Exposure]] -> 17535.553 | H14: =Table21[[#This Row],[Combined Exposure]]/$D$4 -> 0.11052835 | I14: =SUMIF(Table19[Primary theme],Table21[[#This Row],[Primary theme]],Table19[Realized Profit]) -> 814.83797 | J14: =SUMIF(Table19[Primary theme],Table21[[#This Row],[Primary theme]],Table19[Unrealized Profit]) -> 5483.475 | K14: =IFERROR(Table21[[#This Row],[Unrealized Profit]]/Table21[[#This Row],[Cost basis]],"") -> 0.45498171 | L14: =IF(Table21[[#This Row],[Percentage of Stock Exposure]]>Table21[[#This Row],[Target]],TRUE,FALSE) -> TRUE
A15: Bitcoin mining | B15: =SUMIF(Table19[[#All],[Primary theme]],Table21[[#This Row],[Primary theme]],Table19[[#All],[Stock Exposure]]) -> 10475.983 | C15: =SUMIF(Table19[[#All],[Primary theme]],Table21[[#This Row],[Primary theme]],Table19[[#All],[Cost of current position]]) -> 8324.4266 | D15: =Table21[[#This Row],[Stock Exposure]]/$D$5 -> 0.079986846 | E15: 0.07 | F15: =SUMIF(Table19[[#All],[Primary theme]],Table21[[#This Row],[Primary theme]],Table19[[#All],[Option Exposure]]) -> 0 | G15: =Table21[[#This Row],[Option Exposure]]+Table21[[#This Row],[Stock Exposure]] -> 10475.983 | H15: =Table21[[#This Row],[Combined Exposure]]/$D$4 -> 0.066031171 | I15: =SUMIF(Table19[Primary theme],Table21[[#This Row],[Primary theme]],Table19[Realized Profit]) -> -2987.3734 | J15: =SUMIF(Table19[Primary theme],Table21[[#This Row],[Primary theme]],Table19[Unrealized Profit]) -> 2151.5563 | K15: =IFERROR(Table21[[#This Row],[Unrealized Profit]]/Table21[[#This Row],[Cost basis]],"") -> 0.258463 | L15: =IF(Table21[[#This Row],[Percentage of Stock Exposure]]>Table21[[#This Row],[Target]],TRUE,FALSE) -> TRUE
A16: Defense | B16: =SUMIF(Table19[[#All],[Primary theme]],Table21[[#This Row],[Primary theme]],Table19[[#All],[Stock Exposure]]) -> 13867.132 | C16: =SUMIF(Table19[[#All],[Primary theme]],Table21[[#This Row],[Primary theme]],Table19[[#All],[Cost of current position]]) -> 9228.18 | D16: =Table21[[#This Row],[Stock Exposure]]/$D$5 -> 0.10587915 | E16: 0 | F16: =SUMIF(Table19[[#All],[Primary theme]],Table21[[#This Row],[Primary theme]],Table19[[#All],[Option Exposure]]) -> 0 | G16: =Table21[[#This Row],[Option Exposure]]+Table21[[#This Row],[Stock Exposure]] -> 13867.132 | H16: =Table21[[#This Row],[Combined Exposure]]/$D$4 -> 0.087405922 | I16: =SUMIF(Table19[Primary theme],Table21[[#This Row],[Primary theme]],Table19[Realized Profit]) -> 8124.921 | J16: =SUMIF(Table19[Primary theme],Table21[[#This Row],[Primary theme]],Table19[Unrealized Profit]) -> 4638.9516 | K16: =IFERROR(Table21[[#This Row],[Unrealized Profit]]/Table21[[#This Row],[Cost basis]],"") -> 0.50269409 | L16: =IF(Table21[[#This Row],[Percentage of Stock Exposure]]>Table21[[#This Row],[Target]],TRUE,FALSE) -> TRUE
A17: Robotics | B17: =SUMIF(Table19[[#All],[Primary theme]],Table21[[#This Row],[Primary theme]],Table19[[#All],[Stock Exposure]]) -> 8640.34 | C17: =SUMIF(Table19[[#All],[Primary theme]],Table21[[#This Row],[Primary theme]],Table19[[#All],[Cost of current position]]) -> 3859.0748 | D17: =Table21[[#This Row],[Stock Exposure]]/$D$5 -> 0.065971237 | E17: 0 | F17: =SUMIF(Table19[[#All],[Primary theme]],Table21[[#This Row],[Primary theme]],Table19[[#All],[Option Exposure]]) -> 0 | G17: =Table21[[#This Row],[Option Exposure]]+Table21[[#This Row],[Stock Exposure]] -> 8640.34 | H17: =Table21[[#This Row],[Combined Exposure]]/$D$4 -> 0.05446093 | I17: =SUMIF(Table19[Primary theme],Table21[[#This Row],[Primary theme]],Table19[Realized Profit]) -> 3101.7748 | J17: =SUMIF(Table19[Primary theme],Table21[[#This Row],[Primary theme]],Table19[Unrealized Profit]) -> 4854.2352 | K17: =IFERROR(Table21[[#This Row],[Unrealized Profit]]/Table21[[#This Row],[Cost basis]],"") -> 1.2578754 | L17: =IF(Table21[[#This Row],[Percentage of Stock Exposure]]>Table21[[#This Row],[Target]],TRUE,FALSE) -> TRUE
A18: Industrials | B18: =SUMIF(Table19[[#All],[Primary theme]],Table21[[#This Row],[Primary theme]],Table19[[#All],[Stock Exposure]]) -> 12136.151 | C18: =SUMIF(Table19[[#All],[Primary theme]],Table21[[#This Row],[Primary theme]],Table19[[#All],[Cost of current position]]) -> 10123.803 | D18: =Table21[[#This Row],[Stock Exposure]]/$D$5 -> 0.09266266 | E18: 0.03 | F18: =SUMIF(Table19[[#All],[Primary theme]],Table21[[#This Row],[Primary theme]],Table19[[#All],[Option Exposure]]) -> 0 | G18: =Table21[[#This Row],[Option Exposure]]+Table21[[#This Row],[Stock Exposure]] -> 12136.151 | H18: =Table21[[#This Row],[Combined Exposure]]/$D$4 -> 0.076495377 | I18: =SUMIF(Table19[Primary theme],Table21[[#This Row],[Primary theme]],Table19[Realized Profit]) -> 1143.9931 | J18: =SUMIF(Table19[Primary theme],Table21[[#This Row],[Primary theme]],Table19[Unrealized Profit]) -> 2012.3479 | K18: =IFERROR(Table21[[#This Row],[Unrealized Profit]]/Table21[[#This Row],[Cost basis]],"") -> 0.19877391 | L18: =IF(Table21[[#This Row],[Percentage of Stock Exposure]]>Table21[[#This Row],[Target]],TRUE,FALSE) -> TRUE
A19: Technology | B19: =SUMIF(Table19[[#All],[Primary theme]],Table21[[#This Row],[Primary theme]],Table19[[#All],[Stock Exposure]]) -> 1713.505 | C19: =SUMIF(Table19[[#All],[Primary theme]],Table21[[#This Row],[Primary theme]],Table19[[#All],[Cost of current position]]) -> 1891.1596 | D19: =Table21[[#This Row],[Stock Exposure]]/$D$5 -> 0.013083055 | E19: 0.02 | F19: =SUMIF(Table19[[#All],[Primary theme]],Table21[[#This Row],[Primary theme]],Table19[[#All],[Option Exposure]]) -> 0 | G19: =Table21[[#This Row],[Option Exposure]]+Table21[[#This Row],[Stock Exposure]] -> 1713.505 | H19: =Table21[[#This Row],[Combined Exposure]]/$D$4 -> 0.010800394 | I19: =SUMIF(Table19[Primary theme],Table21[[#This Row],[Primary theme]],Table19[Realized Profit]) -> 903.4596 | J19: =SUMIF(Table19[Primary theme],Table21[[#This Row],[Primary theme]],Table19[Unrealized Profit]) -> 677.5954 | K19: =IFERROR(Table21[[#This Row],[Unrealized Profit]]/Table21[[#This Row],[Cost basis]],"") -> 0.35829626 | L19: =IF(Table21[[#This Row],[Percentage of Stock Exposure]]>Table21[[#This Row],[Target]],TRUE,FALSE) -> FALSE
A20: Financials | B20: =SUMIF(Table19[[#All],[Primary theme]],Table21[[#This Row],[Primary theme]],Table19[[#All],[Stock Exposure]]) -> 1932.4775 | C20: =SUMIF(Table19[[#All],[Primary theme]],Table21[[#This Row],[Primary theme]],Table19[[#All],[Cost of current position]]) -> 1068.3817 | D20: =Table21[[#This Row],[Stock Exposure]]/$D$5 -> 0.014754967 | E20: 0.03 | F20: =SUMIF(Table19[[#All],[Primary theme]],Table21[[#This Row],[Primary theme]],Table19[[#All],[Option Exposure]]) -> 0 | G20: =Table21[[#This Row],[Option Exposure]]+Table21[[#This Row],[Stock Exposure]] -> 1932.4775 | H20: =Table21[[#This Row],[Combined Exposure]]/$D$4 -> 0.0121806 | I20: =SUMIF(Table19[Primary theme],Table21[[#This Row],[Primary theme]],Table19[Realized Profit]) -> -1483.1683 | J20: =SUMIF(Table19[Primary theme],Table21[[#This Row],[Primary theme]],Table19[Unrealized Profit]) -> 864.09582 | K20: =IFERROR(Table21[[#This Row],[Unrealized Profit]]/Table21[[#This Row],[Cost basis]],"") -> 0.80878944 | L20: =IF(Table21[[#This Row],[Percentage of Stock Exposure]]>Table21[[#This Row],[Target]],TRUE,FALSE) -> FALSE
A21: Nuclear | B21: =SUMIF(Table19[[#All],[Primary theme]],Table21[[#This Row],[Primary theme]],Table19[[#All],[Stock Exposure]]) -> 2898.4066 | C21: =SUMIF(Table19[[#All],[Primary theme]],Table21[[#This Row],[Primary theme]],Table19[[#All],[Cost of current position]]) -> 2933.9418 | D21: =Table21[[#This Row],[Stock Exposure]]/$D$5 -> 0.022130086 | E21: 0.06 | F21: =SUMIF(Table19[[#All],[Primary theme]],Table21[[#This Row],[Primary theme]],Table19[[#All],[Option Exposure]]) -> 0 | G21: =Table21[[#This Row],[Option Exposure]]+Table21[[#This Row],[Stock Exposure]] -> 2898.4066 | H21: =Table21[[#This Row],[Combined Exposure]]/$D$4 -> 0.018268948 | I21: =SUMIF(Table19[Primary theme],Table21[[#This Row],[Primary theme]],Table19[Realized Profit]) -> 1380.5718 | J21: =SUMIF(Table19[Primary theme],Table21[[#This Row],[Primary theme]],Table19[Unrealized Profit]) -> -35.535206 | K21: =IFERROR(Table21[[#This Row],[Unrealized Profit]]/Table21[[#This Row],[Cost basis]],"") -> -0.012111762 | L21: =IF(Table21[[#This Row],[Percentage of Stock Exposure]]>Table21[[#This Row],[Target]],TRUE,FALSE) -> FALSE
A22: Connectivity | B22: =SUMIF(Table19[[#All],[Primary theme]],Table21[[#This Row],[Primary theme]],Table19[[#All],[Stock Exposure]]) -> 1113.4235 | C22: =SUMIF(Table19[[#All],[Primary theme]],Table21[[#This Row],[Primary theme]],Table19[[#All],[Cost of current position]]) -> 700.35805 | D22: =Table21[[#This Row],[Stock Exposure]]/$D$5 -> 0.0085012772 | E22: 0.05 | F22: =SUMIF(Table19[[#All],[Primary theme]],Table21[[#This Row],[Primary theme]],Table19[[#All],[Option Exposure]]) -> 0 | G22: =Table21[[#This Row],[Option Exposure]]+Table21[[#This Row],[Stock Exposure]] -> 1113.4235 | H22: =Table21[[#This Row],[Combined Exposure]]/$D$4 -> 0.00701802 | I22: =SUMIF(Table19[Primary theme],Table21[[#This Row],[Primary theme]],Table19[Realized Profit]) -> 103.44805 | J22: =SUMIF(Table19[Primary theme],Table21[[#This Row],[Primary theme]],Table19[Unrealized Profit]) -> 413.06545 | K22: =IFERROR(Table21[[#This Row],[Unrealized Profit]]/Table21[[#This Row],[Cost basis]],"") -> 0.58979182 | L22: =IF(Table21[[#This Row],[Percentage of Stock Exposure]]>Table21[[#This Row],[Target]],TRUE,FALSE) -> FALSE
... A50: Materials | B50: =SUMIF(Table19[[#All],[Primary theme]],Table21[[#This Row],[Primary theme]],Table19[[#All],[Stock Exposure]]) -> -296.88 | C50: =SUMIF(Table19[[#All],[Primary theme]],Table21[[#This Row],[Primary theme]],Table19[[#All],[Cost of current position]]) -> 0 | D50: =Table21[[#This Row],[Stock Exposure]]/$D$5 -> -0.0022667558 | E50: 0 | F50: =SUMIF(Table19[[#All],[Primary theme]],Table21[[#This Row],[Primary theme]],Table19[[#All],[Option Exposure]]) -> 0 | G50: =Table21[[#This Row],[Option Exposure]]+Table21[[#This Row],[Stock Exposure]] -> -296.88 | H50: =Table21[[#This Row],[Combined Exposure]]/$D$4 -> -0.0018712644 | I50: =SUMIF(Table19[Primary theme],Table21[[#This Row],[Primary theme]],Table19[Realized Profit]) -> 0 | J50: =SUMIF(Table19[Primary theme],Table21[[#This Row],[Primary theme]],Table19[Unrealized Profit]) -> 0 | K50: =IFERROR(Table21[[#This Row],[Unrealized Profit]]/Table21[[#This Row],[Cost basis]],"") | L50: =IF(Table21[[#This Row],[Percentage of Stock Exposure]]>Table21[[#This Row],[Target]],TRUE,FALSE) -> FALSE

Sheet CryptoPortfolio
A1: Crypto Portfolio | C1: Total CryptoPortfolio Value | D1: =SUM(Table26[[#All],[Current Exposure]]) -> 37073.169 | F1: Total Realized: | G1: =SUM(Table228[Realized Profit]) -> -2062874.7
A3: 1 | B3: 2 | C3: 3 | D3: 4 | E3: 5 | F3: 6 | G3: 7 | H3: 8 | I3: 9 | J3: 10
A4: Asset | B4: Theme | C4: Realized Profit | D4: Unrealized Profit | E4: Blockchain | F4: Current Exposure | G4: Average Entry | H4: How many tokens | I4: Distance from entry | J4: Current Price
A5: SOL | B5: Layer 1 | C5: =IFERROR(VLOOKUP(Table26[[#This Row],[Asset]],Table228[],19,FALSE),0) -> -38.51938 | D5: =IFERROR(VLOOKUP(Table26[[#This Row],[Asset]],Table228[#All],20,FALSE),0) -> 1671.0622 | E5: Solana | F5: =Table26[[#This Row],[How many tokens]]*Table26[[#This Row],[Current Price]] -> 12792.772 | G5: =IFERROR(VLOOKUP(Table26[[#This Row],[Asset]],Table228[#All],16,FALSE),0) -> 147.79366 | H5: =IFERROR(VLOOKUP(Table26[[#This Row],[Asset]],Table228[#All],18,FALSE),0) -> 75.2516 | I5: =IFERROR((Table26[[#This Row],[Current Price]]-Table26[[#This Row],[Average Entry]])/Table26[[#This Row],[Average Entry]],0) -> 0.15025228 | J5: 170
A6: KMNO | B6: Defi | C6: =IFERROR(VLOOKUP(Table26[[#This Row],[Asset]],Table228[],19,FALSE),0) -> -3799.3442 | D6: =IFERROR(VLOOKUP(Table26[[#This Row],[Asset]],Table228[#All],20,FALSE),0) -> 440.80882 | E6: Solana | F6: =Table26[[#This Row],[How many tokens]]*Table26[[#This Row],[Current Price]] -> -859.57882 | G6: =IFERROR(VLOOKUP(Table26[[#This Row],[Asset]],Table228[#All],16,FALSE),0) -> 0.064768343 | H6: =IFERROR(VLOOKUP(Table26[[#This Row],[Asset]],Table228[#All],18,FALSE),0) -> -20077.519 | I6: =IFERROR((Table26[[#This Row],[Current Price]]-Table26[[#This Row],[Average Entry]])/Table26[[#This Row],[Average Entry]],0) -> -0.33898263 | J6: 0.042813
A7: VRTX | B7: Perpetual Exchange | C7: =IFERROR(VLOOKUP(Table26[[#This Row],[Asset]],Table228[],19,FALSE),0) -> -3890.4228 | D7: =IFERROR(VLOOKUP(Table26[[#This Row],[Asset]],Table228[#All],20,FALSE),0) -> -0.044737623 | E7: Arbitrum | F7: =Table26[[#This Row],[How many tokens]]*Table26[[#This Row],[Current Price]] -> 0.0159025 | G7: =IFERROR(VLOOKUP(Table26[[#This Row],[Asset]],Table228[#All],16,FALSE),0) -> 0.095331117 | H7: =IFERROR(VLOOKUP(Table26[[#This Row],[Asset]],Table228[#All],18,FALSE),0) -> 0.6361 | I7: =IFERROR((Table26[[#This Row],[Current Price]]-Table26[[#This Row],[Average Entry]])/Table26[[#This Row],[Average Entry]],0) -> -0.73775614 | J7: 0.025
A8: Jto/jitoSol | C8: =IFERROR(VLOOKUP(Table26[[#This Row],[Asset]],Table228[],19,FALSE),0) -> 0 | D8: =IFERROR(VLOOKUP(Table26[[#This Row],[Asset]],Table228[#All],20,FALSE),0) -> -630 | E8: Solana | F8: =Table26[[#This Row],[How many tokens]]*Table26[[#This Row],[Current Price]] -> 4290 | G8: =IFERROR(VLOOKUP(Table26[[#This Row],[Asset]],Table228[#All],16,FALSE),0) -> 4920 | H8: =IFERROR(VLOOKUP(Table26[[#This Row],[Asset]],Table228[#All],18,FALSE),0) -> 1 | I8: =IFERROR((Table26[[#This Row],[Current Price]]-Table26[[#This Row],[Average Entry]])/Table26[[#This Row],[Average Entry]],0) -> -0.12804878 | J8: 4290
A9: Famous Fox | B9: NFT | C9: =IFERROR(VLOOKUP(Table26[[#This Row],[Asset]],Table228[],19,FALSE),0) -> -4089.5824 | D9: =IFERROR(VLOOKUP(Table26[[#This Row],[Asset]],Table228[#All],20,FALSE),0) -> 0 | E9: Solana | F9: =Table26[[#This Row],[How many tokens]]*Table26[[#This Row],[Current Price]] -> 0 | G9: =IFERROR(VLOOKUP(Table26[[#This Row],[Asset]],Table228[#All],16,FALSE),0) -> 927.90565 | H9: =IFERROR(VLOOKUP(Table26[[#This Row],[Asset]],Table228[#All],18,FALSE),0) -> 0 | I9: =IFERROR((Table26[[#This Row],[Current Price]]-Table26[[#This Row],[Average Entry]])/Table26[[#This Row],[Average Entry]],0) -> -0.31889627 | J9: 632
A10: SEND | B10: AI agent | C10: =IFERROR(VLOOKUP(Table26[[#This Row],[Asset]],Table228[],19,FALSE),0) -> -12004.723 | D10: =IFERROR(VLOOKUP(Table26[[#This Row],[Asset]],Table228[#All],20,FALSE),0) -> 0.0033201484 | E10: Solana | F10: =Table26[[#This Row],[How many tokens]]*Table26[[#This Row],[Current Price]] -> -0.001872871 | G10: =IFERROR(VLOOKUP(Table26[[#This Row],[Asset]],Table228[#All],16,FALSE),0) -> 0.030500346 | H10: =IFERROR(VLOOKUP(Table26[[#This Row],[Asset]],Table228[#All],18,FALSE),0) -> -0.170261 | I10: =IFERROR((Table26[[#This Row],[Current Price]]-Table26[[#This Row],[Average Entry]])/Table26[[#This Row],[Average Entry]],0) -> -0.63934835 | J10: 0.011
